Workbook
Name Slicer_Category: #N/A

Sheet ANALYSIS
A2: REVENUE VS. NP LINE CHART | F2: NET PROFIT MARGIN BY MONTH. LINE CHART
A3: Month | B3: Sum of Net_Sales | C3: Sum of Net_Profit | F3: Month | G3: Average of Net_Margin
A4: Jan | B4: 25431898 | C4: 3598023.4 | F4: Jan | G4: 0.14552576
A5: Feb | B5: 24707423 | C5: 3422624.3 | F5: Feb | G5: 0.13773332
A6: Mar | B6: 19676765 | C6: 3081017.1 | F6: Mar | G6: 0.14769444
A7: Apr | B7: 20153440 | C7: 2790927.7 | F7: Apr | G7: 0.14302242
A8: May | B8: 25565774 | C8: 3808923.4 | F8: May | G8: 0.15178752
A9: Jun | B9: 21861504 | C9: 3305846.1 | F9: Jun | G9: 0.13999304
A10: Jul | B10: 23487080 | C10: 7035193.5 | F10: Jul | G10: 0.30200066
A11: Aug | B11: 22763655 | C11: 6938560.4 | F11: Aug | G11: 0.29903566
A12: Sep | B12: 19424661 | C12: 5547978.5 | F12: Sep | G12: 0.2871961
A13: Oct | B13: 24553827 | C13: 7047912.1 | F13: Oct | G13: 0.30042927
A14: Nov | B14: 29547643 | C14: 8748386.3 | F14: Nov | G14: 0.30408976
A15: Dec | B15: 22859829 | C15: 7078602.7 | F15: Dec | G15: 0.30697347
A18: H1vsH2 discout rate. Coulumn chart | H18: H1vs.H2 cluster column chart
A19: Period | B19: Sum of Gross_Sales | C19: Sum of Discount | F19: Period | G19: Sum of Net_Sales | H19: Sum of Net_Profit | I19: Sum of Discount | J19: Sum of Product_Cost | K19: Sum of Transport_Cost | L19: Sum of Labour_Cost | M19: Sum of Marketing_Cost | N19: Sum of Other_Cost
A20: H1 | B20: 1.488906e+08 | C20: 11493794 | D20: =GETPIVOTDATA("Sum of Discount",$A$19,"Period","H1")/GETPIVOTDATA("Sum of Gross_Sales",$A$19,"Period","H1") -> 0.077196237 | F20: H1 | G20: 1.373968e+08 | H20: 20007362 | I20: 11493794 | J20: 94486123 | K20: 4263524.7 | L20: 8897905.8 | M20: 6193530 | N20: 3548359.1
A21: H2 | B21: 1.4857947e+08 | C21: 5942774.4 | D21: =GETPIVOTDATA("Sum of Discount",$A$19,"Period","H2")/GETPIVOTDATA("Sum of Gross_Sales",$A$19,"Period","H2") -> 0.039997279 | F21: H2 | G21: 1.4263669e+08 | H21: 42396633 | I21: 5942774.4 | J21: 83343998 | K21: 3038280.4 | L21: 7846691.6 | M21: 3587947.9 | N21: 2423142.8
B24: Product profitability. Barchart | F24: Revenue vs. np. Scatter chart
A25: Period | B25: Sum of Net_Sales | C25: Sum of Net_Profit | D25: Average of Net_Margin | F25: Period | G25: Sum of Net_Sales | H25: Sum of Net_Profit
A26: H1 | B26: 1.373968e+08 | C26: 20007362 | D26: 0.14442082 | F26: H1 | G26: 1.373968e+08 | H26: 20007362
A27: H2 | B27: 1.4263669e+08 | C27: 42396633 | D27: 0.30007175 | F27: H2 | G27: 1.4263669e+08 | H27: 42396633
A30: category performance. Cluster bar chart | F30: COST STRUCTURE. STACK COLUMN CHART
A31: Category | B31: Sum of Net_Profit | F31: Period
A32: Beverages | B32: 4960162.3 | E32: Values | F32: H1 | G32: H2
A33: Biscuits | B33: 4071056.3 | E33: Sum of Product_Cost | F33: 94486123 | G33: 83343998
A34: Cooking Oil | B34: 17313620 | E34: Sum of Transport_Cost | F34: 4263524.7 | G34: 3038280.4
A35: Home Care | B35: 18335569 | E35: Sum of Labour_Cost | F35: 8897905.8 | G35: 7846691.6
A36: Paper Products | B36: 11973569 | E36: Sum of Marketing_Cost | F36: 6193530 | G36: 3587947.9
A37: Personal Care | B37: 5750019.3 | E37: Sum of Other_Cost | F37: 3548359.1 | G37: 2423142.8
B40: CUSTOMER PERFORMANCE. HORIZ.. BARCHART | F40: QTY VS. PROFIT. COMBO CHART
A41: Customer | B41: Sum of Net_Sales | C41: Sum of Net_Profit | D41: Average of Net_Margin | F41: Month | G41: Sum of Quantity | H41: Sum of Net_Profit
A42: Abuja Mega Store | B42: 20902645 | C42: 4779874.3 | D42: 0.22518441 | F42: Jan | G42: 10487 | H42: 3598023.4
A43: CityMart | B43: 20432297 | C43: 4461289.8 | D43: 0.20622132 | F43: Feb | G43: 9181 | H43: 3422624.3
A44: Green Basket | B44: 23073488 | C44: 5204439.4 | D44: 0.22940484 | F44: Mar | G44: 8195 | H44: 3081017.1
A45: Ikeja Retail Hub | B45: 23878841 | C45: 5161267.4 | D45: 0.21975627 | F45: Apr | G45: 8159 | H45: 2790927.7
A46: Justrite | B46: 29313343 | C46: 6471242.2 | D46: 0.22241353 | F46: May | G46: 9809 | H46: 3808923.4
A47: Lagos Wholesale Mart | B47: 24850760 | C47: 5659922.1 | D47: 0.22713194 | F47: Jun | G47: 8980 | H47: 3305846.1
A48: Market Square | B48: 23125939 | C48: 5074784.8 | D48: 0.22375098 | F48: Jul | G48: 7879.526 | H48: 7035193.5
A49: Prime Retailers | B49: 20644835 | C49: 4654401.2 | D49: 0.22653345 | F49: Aug | G49: 6585.6352 | H49: 6938560.4
...

Sheet DASHBOARD
B13: =ANALYSIS!C59 -> -0.0020896544 | E13: =ANALYSIS!G59 -> 0.03813691 | H13: =ANALYSIS!C64 -> 1.1190517 | L13: =ANALYSIS!G65 -> 0.15565093 | O13: =ANALYSIS!G70 -> -0.1179234 | R13: =ANALYSIS!G70 -> -0.1179234

Sheet Transactions
A1: Date | B1: Invoice_ID | C1: Customer | D1: Product | E1: Category | F1: Region | G1: Salesperson | H1: Sales_Channel | I1: Quantity | J1: Unit_Price | K1: Gross_Sales | L1: Discount | M1: Net_Sales | N1: Product_Cost | O1: Transport_Cost | P1: Labour_Cost | Q1: Marketing_Cost | R1: Other_Cost | S1: Total_Cost | T1: Gross_Profit | U1: Net_Profit | V1: Net_Margin | W1: Payment_Status | X1: Month | Y1: Month_No | Z1: Period
A2: 45658 | B2: INV-01394 | C2: Supermart | D2: Premium Malt | E2: Beverages | F2: Abuja | G2: Daniel | H2: Distributor | I2: 85 | J2: 1144.69 | K2: =Table1[[#This Row],[Quantity]]*Table1[[#This Row],[Unit_Price]] -> 97298.65 | L2: 7232.67 | M2: =Table1[[#This Row],[Gross_Sales]]-Table1[[#This Row],[Discount]] -> 90065.98 | N2: 55988.34 | O2: 3447.96 | P2: 5450.98 | Q2: 3596.33 | R2: 2186.21 | S2: =SUM(Table1[[#This Row],[Product_Cost]:[Other_Cost]]) -> 70669.82 | T2: =Table1[[#This Row],[Net_Sales]]-Table1[[#This Row],[Product_Cost]] -> 34077.64 | U2: =Table1[[#This Row],[Net_Sales]]-Table1[[#This Row],[Total_Cost]] -> 19396.16 | V2: =Table1[[#This Row],[Net_Profit]]/Table1[[#This Row],[Net_Sales]] -> 0.21535501 | W2: Paid | X2: Jan | Y2: 1 | Z2: =IF(Table1[[#This Row],[Month_No]]<=6, "H1","H2") -> H1
A3: 45658 | B3: INV-00118 | C3: Justrite | D3: Standard Tissue | E3: Paper Products | F3: Port Harcourt | G3: Samuel | H3: Wholesale | I3: 91 | J3: 4110.11 | K3: =Table1[[#This Row],[Quantity]]*Table1[[#This Row],[Unit_Price]] -> 374020.01 | L3: 29324.64 | M3: =Table1[[#This Row],[Gross_Sales]]-Table1[[#This Row],[Discount]] -> 344695.37 | N3: 244324.21 | O3: 15243.21 | P3: 23431.33 | Q3: 18619.47 | R3: 9087.53 | S3: =SUM(Table1[[#This Row],[Product_Cost]:[Other_Cost]]) -> 310705.75 | T3: =Table1[[#This Row],[Net_Sales]]-Table1[[#This Row],[Product_Cost]] -> 100371.16 | U3: =Table1[[#This Row],[Net_Sales]]-Table1[[#This Row],[Total_Cost]] -> 33989.62 | V3: =Table1[[#This Row],[Net_Profit]]/Table1[[#This Row],[Net_Sales]] -> 0.098607707 | W3: Paid | X3: Jan | Y3: 1 | Z3: =IF(Table1[[#This Row],[Month_No]]<=6, "H1","H2") -> H1
A4: 45658 | B4: INV-01194 | C4: CityMart | D4: Basic Detergent 1kg | E4: Home Care | F4: Ibadan | G4: Daniel | H4: Supermarket | I4: 77 | J4: 4319.05 | K4: =Table1[[#This Row],[Quantity]]*Table1[[#This Row],[Unit_Price]] -> 332566.85 | L4: 22792.49 | M4: =Table1[[#This Row],[Gross_Sales]]-Table1[[#This Row],[Discount]] -> 309774.36 | N4: 216457.89 | O4: 9753.16 | P4: 19459.69 | Q4: 16261.06 | R4: 8627.59 | S4: =SUM(Table1[[#This Row],[Product_Cost]:[Other_Cost]]) -> 270559.39 | T4: =Table1[[#This Row],[Net_Sales]]-Table1[[#This Row],[Product_Cost]] -> 93316.47 | U4: =Table1[[#This Row],[Net_Sales]]-Table1[[#This Row],[Total_Cost]] -> 39214.97 | V4: =Table1[[#This Row],[Net_Profit]]/Table1[[#This Row],[Net_Sales]] -> 0.12659205 | W4: Paid | X4: Jan | Y4: 1 | Z4: =IF(Table1[[#This Row],[Month_No]]<=6, "H1","H2") -> H1
A5: 45659 | B5: INV-01021 | C5: Green Basket | D5: Standard Biscuit | E5: Biscuits | F5: Lagos | G5: Daniel | H5: Supermarket | I5: 128 | J5: 791.39 | K5: =Table1[[#This Row],[Quantity]]*Table1[[#This Row],[Unit_Price]] -> 101297.92 | L5: 8033.06 | M5: =Table1[[#This Row],[Gross_Sales]]-Table1[[#This Row],[Discount]] -> 93264.86 | N5: 61727.91 | O5: 2654.58 | P5: 5524.49 | Q5: 3952.88 | R5: 2057.13 | S5: =SUM(Table1[[#This Row],[Product_Cost]:[Other_Cost]]) -> 75916.99 | T5: =Table1[[#This Row],[Net_Sales]]-Table1[[#This Row],[Product_Cost]] -> 31536.95 | U5: =Table1[[#This Row],[Net_Sales]]-Table1[[#This Row],[Total_Cost]] -> 17347.87 | V5: =Table1[[#This Row],[Net_Profit]]/Table1[[#This Row],[Net_Sales]] -> 0.1860065 | W5: Paid | X5: Jan | Y5: 1 | Z5: =IF(Table1[[#This Row],[Month_No]]<=6, "H1","H2") -> H1
A6: 45659 | B6: INV-00049 | C6: Supermart | D6: Standard Biscuit | E6: Biscuits | F6: Port Harcourt | G6: Daniel | H6: Wholesale | I6: 65 | J6: 780.58 | K6: =Table1[[#This Row],[Quantity]]*Table1[[#This Row],[Unit_Price]] -> 50737.7 | L6: 3969.3 | M6: =Table1[[#This Row],[Gross_Sales]]-Table1[[#This Row],[Discount]] -> 46768.4 | N6: 32236.14 | O6: 1978.98 | P6: 3094.32 | Q6: 1647.78 | R6: 1231.35 | S6: =SUM(Table1[[#This Row],[Product_Cost]:[Other_Cost]]) -> 40188.57 | T6: =Table1[[#This Row],[Net_Sales]]-Table1[[#This Row],[Product_Cost]] -> 14532.26 | U6: =Table1[[#This Row],[Net_Sales]]-Table1[[#This Row],[Total_Cost]] -> 6579.83 | V6: =Table1[[#This Row],[Net_Profit]]/Table1[[#This Row],[Net_Sales]] -> 0.14068965 | W6: Paid | X6: Jan | Y6: 1 | Z6: =IF(Table1[[#This Row],[Month_No]]<=6, "H1","H2") -> H1
A7: 45659 | B7: INV-00581 | C7: Market Square | D7: Premium Bath Soap | E7: Personal Care | F7: Port Harcourt | G7: Ibrahim | H7: Retail | I7: 92 | J7: 3115.2 | K7: =Table1[[#This Row],[Quantity]]*Table1[[#This Row],[Unit_Price]] -> 286598.4 | L7: 22867.16 | M7: =Table1[[#This Row],[Gross_Sales]]-Table1[[#This Row],[Discount]] -> 263731.24 | N7: 154129.31 | O7: 10322.62 | P7: 18582.92 | Q7: 10921.44 | R7: 5925.04 | S7: =SUM(Table1[[#This Row],[Product_Cost]:[Other_Cost]]) -> 199881.33 | T7: =Table1[[#This Row],[Net_Sales]]-Table1[[#This Row],[Product_Cost]] -> 109601.93 | U7: =Table1[[#This Row],[Net_Sales]]-Table1[[#This Row],[Total_Cost]] -> 63849.91 | V7: =Table1[[#This Row],[Net_Profit]]/Table1[[#This Row],[Net_Sales]] -> 0.24210219 | W7: Paid | X7: Jan | Y7: 1 | Z7: =IF(Table1[[#This Row],[Month_No]]<=6, "H1","H2") -> H1
A8: 45659 | B8: INV-00586 | C8: CityMart | D8: Standard Tissue | E8: Paper Products | F8: Lagos | G8: Mary | H8: Supermarket | I8: 69 | J8: 4325.99 | K8: =Table1[[#This Row],[Quantity]]*Table1[[#This Row],[Unit_Price]] -> 298493.31 | L8: 18750.04 | M8: =Table1[[#This Row],[Gross_Sales]]-Table1[[#This Row],[Discount]] -> 279743.27 | N8: 207341.39 | O8: 7961.25 | P8: 16491.26 | Q8: 14688.13 | R8: 7754.71 | S8: =SUM(Table1[[#This Row],[Product_Cost]:[Other_Cost]]) -> 254236.74 | T8: =Table1[[#This Row],[Net_Sales]]-Table1[[#This Row],[Product_Cost]] -> 72401.88 | U8: =Table1[[#This Row],[Net_Sales]]-Table1[[#This Row],[Total_Cost]] -> 25506.53 | V8: =Table1[[#This Row],[Net_Profit]]/Table1[[#This Row],[Net_Sales]] -> 0.091178351 | W8: Paid | X8: Jan | Y8: 1 | Z8: =IF(Table1[[#This Row],[Month_No]]<=6, "H1","H2") -> H1
A9: 45659 | B9: INV-01051 | C9: Prime Retailers | D9: Standard Tissue | E9: Paper Products | F9: Lagos | G9: Tunde | H9: Wholesale | I9: 64 | J9: 4077.64 | K9: =Table1[[#This Row],[Quantity]]*Table1[[#This Row],[Unit_Price]] -> 260968.96 | L9: 24552.09 | M9: =Table1[[#This Row],[Gross_Sales]]-Table1[[#This Row],[Discount]] -> 236416.87 | N9: 174115.44 | O9: 6289.75 | P9: 16286.48 | Q9: 10638.51 | R9: 7538.94 | S9: =SUM(Table1[[#This Row],[Product_Cost]:[Other_Cost]]) -> 214869.12 | T9: =Table1[[#This Row],[Net_Sales]]-Table1[[#This Row],[Product_Cost]] -> 62301.43 | U9: =Table1[[#This Row],[Net_Sales]]-Table1[[#This Row],[Total_Cost]] -> 21547.75 | V9: =Table1[[#This Row],[Net_Profit]]/Table1[[#This Row],[Net_Sales]] -> 0.091143031 | W9: Paid | X9: Jan | Y9: 1 | Z9: =IF(Table1[[#This Row],[Month_No]]<=6, "H1","H2") -> H1
A10: 45659 | B10: INV-01254 | C10: Prime Retailers | D10: Premium Biscuit | E10: Biscuits | F10: Abuja | G10: Ibrahim | H10: Supermarket | I10: 29 | J10: 1358.51 | K10: =Table1[[#This Row],[Quantity]]*Table1[[#This Row],[Unit_Price]] -> 39396.79 | L10: 2696.87 | M10: =Table1[[#This Row],[Gross_Sales]]-Table1[[#This Row],[Discount]] -> 36699.92 | N10: 19905.91 | O10: 1406.55 | P10: 2627.33 | Q10: 1764.99 | R10: 1172.69 | S10: =SUM(Table1[[#This Row],[Product_Cost]:[Other_Cost]]) -> 26877.47 | T10: =Table1[[#This Row],[Net_Sales]]-Table1[[#This Row],[Product_Cost]] -> 16794.01 | U10: =Table1[[#This Row],[Net_Sales]]-Table1[[#This Row],[Total_Cost]] -> 9822.45 | V10: =Table1[[#This Row],[Net_Profit]]/Table1[[#This Row],[Net_Sales]] -> 0.26764227 | W10: Paid | X10: Jan | Y10: 1 | Z10: =IF(Table1[[#This Row],[Month_No]]<=6, "H1","H2") -> H1
A11: 45659 | B11: INV-00294 | C11: CityMart | D11: Bottled Water | E11: Beverages | F11: Lagos | G11: Samuel | H11: Wholesale | I11: 109 | J11: 342.8 | K11: =Table1[[#This Row],[Quantity]]*Table1[[#This Row],[Unit_Price]] -> 37365.2 | L11: 3125.04 | M11: =Table1[[#This Row],[Gross_Sales]]-Table1[[#This Row],[Discount]] -> 34240.16 | N11: 26130.23 | O11: 820.49 | P11: 1925.8 | Q11: 1779.42 | R11: 774 | S11: =SUM(Table1[[#This Row],[Product_Cost]:[Other_Cost]]) -> 31429.94 | T11: =Table1[[#This Row],[Net_Sales]]-Table1[[#This Row],[Product_Cost]] -> 8109.93 | U11: =Table1[[#This Row],[Net_Sales]]-Table1[[#This Row],[Total_Cost]] -> 2810.22 | V11: =Table1[[#This Row],[Net_Profit]]/Table1[[#This Row],[Net_Sales]] -> 0.082073799 | W11: Paid | X11: Jan | Y11: 1 | Z11: =IF(Table1[[#This Row],[Month_No]]<=6, "H1","H2") -> H1
A12: 45660 | B12: INV-01036 | C12: Lagos Wholesale Mart | D12: Premium Malt | E12: Beverages | F12: Lagos | G12: Fatima | H12: Wholesale | I12: 102 | J12: 1102.13 | K12: =Table1[[#This Row],[Quantity]]*Table1[[#This Row],[Unit_Price]] -> 112417.26 | L12: 9894.1 | M12: =Table1[[#This Row],[Gross_Sales]]-Table1[[#This Row],[Discount]] -> 102523.16 | N12: 60067.34 | O12: 2597.08 | P12: 7106.36 | Q12: 4993.15 | R12: 2064.4 | S12: =SUM(Table1[[#This Row],[Product_Cost]:[Other_Cost]]) -> 76828.33 | T12: =Table1[[#This Row],[Net_Sales]]-Table1[[#This Row],[Product_Cost]] -> 42455.82 | U12: =Table1[[#This Row],[Net_Sales]]-Table1[[#This Row],[Total_Cost]] -> 25694.83 | V12: =Table1[[#This Row],[Net_Profit]]/Table1[[#This Row],[Net_Sales]] -> 0.25062464 | W12: Pending | X12: Jan | Y12: 1 | Z12: =IF(Table1[[#This Row],[Month_No]]<=6, "H1","H2") -> H1
A13: 45660 | B13: INV-01376 | C13: Lagos Wholesale Mart | D13: Standard Cooking Oil 1L | E13: Cooking Oil | F13: Abuja | G13: Emeka | H13: Supermarket | I13: 59 | J13: 5036.08 | K13: =Table1[[#This Row],[Quantity]]*Table1[[#This Row],[Unit_Price]] -> 297128.72 | L13: 26444.22 | M13: =Table1[[#This Row],[Gross_Sales]]-Table1[[#This Row],[Discount]] -> 270684.5 | N13: 207277.12 | O13: 10236.16 | P13: 18287.66 | Q13: 10421.03 | R13: 5551.79 | S13: =SUM(Table1[[#This Row],[Product_Cost]:[Other_Cost]]) -> 251773.76 | T13: =Table1[[#This Row],[Net_Sales]]-Table1[[#This Row],[Product_Cost]] -> 63407.38 | U13: =Table1[[#This Row],[Net_Sales]]-Table1[[#This Row],[Total_Cost]] -> 18910.74 | V13: =Table1[[#This Row],[Net_Profit]]/Table1[[#This Row],[Net_Sales]] -> 0.069862663 | W13: Paid | X13: Jan | Y13: 1 | Z13: =IF(Table1[[#This Row],[Month_No]]<=6, "H1","H2") -> H1
... A1441: 46022 | B1441: INV-00992 | C1441: ValuePoint | D1441: Standard Tissue | E1441: Paper Products | F1441: Ibadan | G1441: Mary | H1441: Retail | I1441: 64.365454 | J1441: 4975.2 | K1441: =Table1[[#This Row],[Quantity]]*Table1[[#This Row],[Unit_Price]] -> 320231.01 | L1441: 6527.27 | M1441: =Table1[[#This Row],[Gross_Sales]]-Table1[[#This Row],[Discount]] -> 313703.74 | N1441: 215880.53 | O1441: 6342.52 | P1441: 16751.65 | Q1441: 8559.33 | R1441: 5880.73 | S1441: =SUM(Table1[[#This Row],[Product_Cost]:[Other_Cost]]) -> 253414.76 | T1441: =Table1[[#This Row],[Net_Sales]]-Table1[[#This Row],[Product_Cost]] -> 97823.207 | U1441: =Table1[[#This Row],[Net_Sales]]-Table1[[#This Row],[Total_Cost]] -> 60288.977 | V1441: =Table1[[#This Row],[Net_Profit]]/Table1[[#This Row],[Net_Sales]] -> 0.19218444 | W1441: Paid | X1441: Dec | Y1441: 12 | Z1441: =IF(Table1[[#This Row],[Month_No]]<=6, "H1","H2") -> H2
